<?xml version="1.0"?>
<!--
  Robot: asket
  Generated by: LinkForge v1.3.4
  https://github.com/arounamounchili/linkforge
  Date: 2026-05-08 18:18:56
-->
<robot xmlns:xacro="http://www.ros.org/wiki/xacro" name="asket">
  <!-- Properties -->
  <xacro:property name="hull" value="0.073237 0.073237 0.073237 1" />
  <xacro:property name="camera_width" value="0.065" />
  <xacro:property name="camera_depth" value="0.075" />
  <xacro:property name="camera_height" value="0.045" />
  <xacro:property name="Lidar_radius" value="0.032" />
  <!-- Materials -->
  <material name="hull">
    <color rgba="${hull}" />
  </material>
  <!-- Links -->
  <link name="GPS">
    <inertial>
      <mass value="0.047" />
      <inertia ixx="0.000064" ixy="0" ixz="0" iyy="0.000064" iyz="0" izz="0.000015" />
    </inertial>
    <visual>
      <geometry>
        <cylinder radius="0.025" length="0.12" />
      </geometry>
    </visual>
    <collision>
      <geometry>
        <cylinder radius="0.025" length="0.12" />
      </geometry>
    </collision>
  </link>
  <link name="L_prop_blade">
    <inertial>
      <mass value="0.015" />
      <inertia ixx="6.9095913e-06" ixy="-2.3902956e-15" ixz="-1.4544952e-13" iyy="3.4860454e-06" iyz="-8.413842e-14" izz="3.4860457e-06" />
    </inertial>
    <visual>
      <geometry>
        <mesh filename="meshes/L_prop_blade_visual.obj" />
      </geometry>
    </visual>
    <collision>
      <geometry>
        <mesh filename="meshes/L_prop_blade_collision.stl" />
      </geometry>
    </collision>
  </link>
  <link name="L_prop_body">
    <inertial>
      <mass value="0.14" />
      <inertia ixx="0.000108986824" ixy="2.166276e-09" ixz="-2.3072687e-08" iyy="7.345061e-05" iyz="-5.3766197e-08" izz="6.267224e-05" />
    </inertial>
    <visual>
      <origin xyz="0 0 -0.02131" rpy="0 0 0" />
      <geometry>
        <mesh filename="meshes/L_prop_body_visual.obj" />
      </geometry>
    </visual>
    <collision>
      <origin xyz="0 0 -0.02131" rpy="0 0 0" />
      <geometry>
        <mesh filename="meshes/L_prop_body_collision.stl" />
      </geometry>
    </collision>
  </link>
  <link name="Lidar">
    <inertial>
      <mass value="0.05" />
      <inertia ixx="0.000017" ixy="0" ixz="0" iyy="0.000017" iyz="0" izz="0.000026" />
    </inertial>
    <visual>
      <geometry>
        <cylinder radius="${Lidar_radius}" length="0.03" />
      </geometry>
    </visual>
    <collision>
      <geometry>
        <cylinder radius="${Lidar_radius}" length="0.03" />
      </geometry>
    </collision>
  </link>
  <link name="Lidar_joint">
    <inertial>
      <mass value="0.015" />
      <inertia ixx="0.000006" ixy="0" ixz="0" iyy="0.000006" iyz="0" izz="0.000008" />
    </inertial>
    <visual>
      <geometry>
        <cylinder radius="${Lidar_radius}" length="0.045" />
      </geometry>
    </visual>
    <collision>
      <geometry>
        <cylinder radius="${Lidar_radius}" length="0.045" />
      </geometry>
    </collision>
  </link>
  <link name="back_camera">
    <inertial>
      <mass value="0.03" />
      <inertia ixx="0.000019" ixy="0" ixz="0" iyy="0.000016" iyz="0" izz="0.000025" />
    </inertial>
    <visual>
      <geometry>
        <box size="${camera_width} ${camera_depth} ${camera_height}" />
      </geometry>
    </visual>
    <collision>
      <geometry>
        <box size="${camera_width} ${camera_depth} ${camera_height}" />
      </geometry>
    </collision>
  </link>
  <link name="front_camera">
    <inertial>
      <mass value="0.03" />
      <inertia ixx="0.000019" ixy="0" ixz="0" iyy="0.000016" iyz="0" izz="0.000025" />
    </inertial>
    <visual>
      <geometry>
        <box size="${camera_width} ${camera_depth} ${camera_height}" />
      </geometry>
    </visual>
    <collision>
      <geometry>
        <box size="${camera_width} ${camera_depth} ${camera_height}" />
      </geometry>
    </collision>
  </link>
  <link name="hull">
    <inertial>
      <mass value="14" />
      <inertia ixx="0.4626108" ixy="8.572913e-05" ixz="-8.047186e-05" iyy="1.6358644" iyz="-3.3231427e-05" izz="1.8897439" />
    </inertial>
    <visual>
      <origin xyz="0.05313 -0.000017 -0.013484" rpy="0 0 0" />
      <geometry>
        <mesh filename="meshes/hull_visual.obj" />
      </geometry>
      <material name="hull" />
    </visual>
    <collision>
      <origin xyz="0.053118 -0.000017 -0.013613" rpy="0 0 0" />
      <geometry>
        <mesh filename="meshes/hull_collision.stl" />
      </geometry>
    </collision>
  </link>
  <link name="px4">
    <inertial>
      <mass value="0.031" />
      <inertia ixx="0.000006" ixy="0" ixz="0" iyy="0.00002" iyz="0" izz="0.000024" />
    </inertial>
    <visual>
      <geometry>
        <box size="0.085 0.045 0.02" />
      </geometry>
    </visual>
    <collision>
      <origin xyz="0 0 0" rpy="0 0 0" />
      <geometry>
        <box size="0.085 0.045 0.02" />
      </geometry>
    </collision>
  </link>
  <link name="r_prop_blade">
    <inertial>
      <mass value="0.015" />
      <inertia ixx="6.9095913e-06" ixy="-2.3902956e-15" ixz="-1.4544952e-13" iyy="3.4860454e-06" iyz="-8.413842e-14" izz="3.4860457e-06" />
    </inertial>
    <visual>
      <geometry>
        <mesh filename="meshes/r_prop_blade_visual.obj" />
      </geometry>
    </visual>
    <collision>
      <geometry>
        <mesh filename="meshes/r_prop_blade_collision.stl" />
      </geometry>
    </collision>
  </link>
  <link name="r_prop_body">
    <inertial>
      <mass value="0.14" />
      <inertia ixx="0.00010898682" ixy="-2.1663829e-09" ixz="-2.3079071e-08" iyy="7.345056e-05" iyz="5.3650595e-08" izz="6.26723e-05" />
    </inertial>
    <visual>
      <origin xyz="0 0 -0.021311" rpy="0 0 0" />
      <geometry>
        <mesh filename="meshes/r_prop_body_visual.obj" />
      </geometry>
    </visual>
    <collision>
      <origin xyz="0 0 -0.021311" rpy="0 0 0" />
      <geometry>
        <mesh filename="meshes/r_prop_body_collision.stl" />
      </geometry>
    </collision>
  </link>
  <!-- Joints -->
  <joint name="GPS_joint" type="fixed">
    <origin xyz="-0.18827 0 0.174775" rpy="0 0 0" />
    <parent link="hull" />
    <child link="GPS" />
  </joint>
  <joint name="L_prop_blade_joint" type="continuous">
    <origin xyz="0 0 -0.025" rpy="0 0 0" />
    <parent link="L_prop_body" />
    <child link="L_prop_blade" />
    <axis xyz="1 0 0" />
    <dynamics damping="0.01" friction="0" />
  </joint>
  <joint name="L_prop_body_joint" type="fixed">
    <origin xyz="-0.65 0.28 -0.1" rpy="0 0 0" />
    <parent link="hull" />
    <child link="L_prop_body" />
  </joint>
  <joint name="Lidar_joint_001" type="fixed">
    <origin xyz="0 0 0.0375" rpy="0 0 0" />
    <parent link="Lidar_joint" />
    <child link="Lidar" />
  </joint>
  <joint name="Lidar_joint_joint" type="fixed">
    <origin xyz="-0.103585 0 0.137275" rpy="0 0 -1.570796" />
    <parent link="hull" />
    <child link="Lidar_joint" />
  </joint>
  <joint name="back_camera_joint" type="fixed">
    <origin xyz="-0.62 -0.02 0.137275" rpy="0 1.570796 0" />
    <parent link="hull" />
    <child link="back_camera" />
  </joint>
  <joint name="front_camera_joint" type="fixed">
    <origin xyz="0 0.02 0.137275" rpy="0 1.570796 0" />
    <parent link="hull" />
    <child link="front_camera" />
  </joint>
  <joint name="px4_joint" type="fixed">
    <parent link="hull" />
    <child link="px4" />
  </joint>
  <joint name="r_prop_blade_joint" type="continuous">
    <origin xyz="0 0 -0.025" rpy="0 0 0" />
    <parent link="r_prop_body" />
    <child link="r_prop_blade" />
    <axis xyz="1 0 0" />
    <dynamics damping="0.01" friction="0" />
  </joint>
  <joint name="r_prop_body_joint" type="fixed">
    <origin xyz="-0.65 -0.28 -0.1" rpy="0 0 0" />
    <parent link="hull" />
    <child link="r_prop_body" />
  </joint>
  <!-- ROS2 Control -->
  <ros2_control name="GazeboSimSystem" type="system">
    <hardware>
      <plugin>gz_ros2_control/GazeboSimSystem</plugin>
    </hardware>
    <joint name="L_prop_blade_joint">
      <command_interface name="velocity" />
      <state_interface name="velocity" />
    </joint>
    <joint name="r_prop_blade_joint">
      <command_interface name="velocity" />
      <state_interface name="velocity" />
    </joint>
  </ros2_control>
  <!-- Gazebo -->
  <gazebo>
    <plugin name="gazebo_ros2_control" filename="gz_ros2_control::GazeboSimROS2ControlPlugin">
      <parameters>$(find robot_description)/config/controllers.yaml</parameters>
    </plugin>
  </gazebo>
  <!-- Sensors -->
  <gazebo reference="front_camera">
    <sensor name="front_camera_sensor" type="camera">
      <always_on>true</always_on>
      <update_rate>30</update_rate>
      <visualize>false</visualize>
      <topic>/front_camera_driver/image_raw</topic>
      <camera>
        <horizontal_fov>1.570796</horizontal_fov>
        <image>
          <width>640</width>
          <height>480</height>
          <format>R8G8B8</format>
        </image>
        <clip>
          <near>0.1</near>
          <far>100</far>
        </clip>
      </camera>
    </sensor>
  </gazebo>
  <gazebo reference="back_camera">
    <sensor name="back_camera_sensor" type="camera">
      <always_on>true</always_on>
      <update_rate>30</update_rate>
      <visualize>false</visualize>
      <topic>/back_camera_driver/image_raw</topic>
      <camera>
        <horizontal_fov>1.570796</horizontal_fov>
        <image>
          <width>640</width>
          <height>480</height>
          <format>R8G8B8</format>
        </image>
        <clip>
          <near>0.1</near>
          <far>100</far>
        </clip>
      </camera>
    </sensor>
  </gazebo>
  <gazebo reference="Lidar">
    <sensor name="Lidar_sensor" type="gpu_lidar">
      <always_on>true</always_on>
      <update_rate>15</update_rate>
      <visualize>false</visualize>
      <topic>/lidar_driver/scan_raw</topic>
      <ray>
        <scan>
          <horizontal>
            <samples>640</samples>
            <resolution>1</resolution>
            <min_angle>-1.570796</min_angle>
            <max_angle>1.570796</max_angle>
          </horizontal>
        </scan>
        <range>
          <min>0.1</min>
          <max>10</max>
          <resolution>0.01</resolution>
        </range>
      </ray>
    </sensor>
  </gazebo>
  <gazebo reference="GPS">
    <sensor name="GPS_sensor" type="navsat">
      <always_on>true</always_on>
      <update_rate>5</update_rate>
      <visualize>false</visualize>
      <topic>/gps_driver/gps_raw</topic>
      <navsat />
    </sensor>
  </gazebo>
  <gazebo reference="px4">
    <sensor name="px4_sensor" type="imu">
      <always_on>true</always_on>
      <update_rate>200</update_rate>
      <visualize>false</visualize>
      <topic>/imu_driver/imu_raw</topic>
      <imu />
    </sensor>
  </gazebo>
</robot>